# 例外

---

## 例外とは

Servletを実装する際、doGetメソッドやdoPostメソッドは以下のように宣言していました。

```java
protected void doGet(HttpServletRequest request, HttpServletResponse response) throws ServletException, IOException {

}
protected void doPost(HttpServletRequest request, HttpServletResponse response) throws ServletException, IOException {

}
```

この「throws」や「Exception」はエラーに関係しています。
プログラムのエラー（不具合）は大きく2種類に分類することができます。
一つ目はコンパイルエラー、二つ目は実行時エラーです。
Javaでは実行時エラーのことを例外と呼び、その例外に対する処理を例外処理と呼びます。

例外（Exception）とは簡単にいえば「エラー」のことで、例外処理といえば「エラー処理」を指します。
先ほどもあったように、エラーには「コンパイルエラー」と「実行時エラー」の2種類があります。
Javaでは実行時エラー、つまり、「プログラム実行中に発生したエラー」の対処方法をプログラマが決めておくことができます。

---

## 主な例外

* ArrayIndexOutOfBoundsException
  * 配列の長さを超えた要素を参照しようとした時に発生する例外
* FileNotFoundException
  * 存在しないファイルにアクセスしようとした時に発生する例外
* IllegalArgumentException
  * 引数に異常な値を設定して呼び出そうとした時に発生する例外
* OutOfMemoryError
  * メモリが足りなくなったときに発生する例外

ArrayIndexOutOfBoundsExceptionは、配列の長さを超えた要素を参照しようとした時に発生する例外です。

![picture 11](/images/329f3a70e3d36b16a3568383f2a51693370145438a239c888425a2fcf2a6b387.png)  

---

実際に例外を発生させて確認します。
新しくJavaプロジェクトを作成してください。
　(プロジェクト名:java2_07_exception)
以下のプログラムを作成して、実行結果を確認してください。

```java
public class TryCatchTest {
    public static void main(String[] args) {
        int[] myarray = new int[3]; // 長さ3の配列

        System.out.println("代入します");

        myarray[100] = 0; // 100番の箱（用意していない箱）に値を入れる

        System.out.println("代入しました");
    }
}
```

結果

```text
代入します
Exception in thread "main" java.lang.ArrayIndexOutOfBoundsException: 100
at TryCatchTest.main(TryCatchTest.java:9)
```

---

(表示されるメッセージの順番は異なる場合があります)
「代入します」までは出力されています。
その次の「myarray[100] = 0;」で配列の長さを超えた添え字を指定し、ArrayIndexOutOfBoundsExceptionが発生しています。
このように例外が発生すると、それ以降の処理が行われません。

例外が発生すると、システムは停止してしまいます。
そのため、例外が発生しても動くように、例外処理をする必要があります。

---

## 例外処理 try~catch

次に例外に対する例外処理を行います。
以下のように変更して、実行結果を確認してください。

```java
public class TryCatchTest {
    public static void main(String[] args) {
        int[] myarray = new int[3]; // 長さ3の配列

        System.out.println("代入します");
        try {
            myarray[100] = 0; // 100番の箱（用意していない箱）に値を入れる
        } catch (ArrayIndexOutOfBoundsException e) {
            e.printStackTrace();
        }
        System.out.println("代入しました");
    }
}
```

実行すると以下のような結果になります。
　(表示されるメッセージの順番は異なる場合があります)
先ほどと同じように例外が発生していますが、処理は継続し、「代入しました」と出力されています。

```text
代入します
java.lang.ArrayIndexOutOfBoundsException: 100
    at TryCatchTest.main(TryCatchTest.java:9)
代入しました
```

---

Javaでは「try ～ catch」の構文を使用して例外処理をすることで、例外が発生しても処理を継続させることができます。

構文

```java
try {
    処理
} catch (例外の型 変数名) {
    例外発生時の処理
}
```

「try ～ catch」で囲んだ部分が「本来の処理」です。
処理の前後を「try ～ catch」で囲むことで、囲んだ範囲で発生する例外を処理することができます。

catchの後の()の中身が「例外の型と変数名」です。
「ここに書いた型の例外」が処理の中で発生した場合、処理がcatchに飛び、例外が発生した時の処理を行うことができます。

```java
catch (ArrayIndexOutOfBoundsException e) {
```

最後に以下のcatchブロック部分が「例外が発生したときの処理」です。
printStackTraceメソッドは例外の情報を出力してくれるメソッドです。

---

## 複数の例外処理 try ～ catch ～ catch …

以下のようにcatchを追加していくことで複数の例外を処理することができます。

```java
try {
    処理
} catch (例外の型 変数名) {
    例外発生時の処理
} catch (例外の型 変数名) {
    例外発生時の処理
}
```

Java7からは以下のように|で複数の例外を指定することも可能です。

```java
try {
    
} catch(IOException | ClassNotFoundException e) { 

}

```

---

実際に試していきます。
以下のようなプログラムを作成して、実行結果を確認してください。

```java
public class TryCatchCatchTest {
    public static void main(String[] args) {
        int[] array = { 0 };
        try {
            System.out.println(1 / array[1]);
        } catch (ArrayIndexOutOfBoundsException e) {
            System.out.println("ArrayIndexOutOfBoundsException");
        } catch (ArithmeticException e) {
            System.out.println("ArithmeticException");
        }
    }
}
```

```text
ArrayIndexOutOfBoundsException
```

---

次は以下のように変更して、実行結果を確認してください。

```java
public class TryCatchCatchTest {
    public static void main(String[] args) {
        int[] array = { 0 };
        try {
            System.out.println(1 / array[0]);
        } catch (ArrayIndexOutOfBoundsException e) {
            System.out.println("ArrayIndexOutOfBoundsException");
        } catch (ArithmeticException e) {
            System.out.println("ArithmeticException");
        }
    }
}
```

実行すると以下のような結果になります。
この例外は「0除算」をしようとした場合に発生する例外です。
このように、発生した例外に応じた例外処理を行うことができます。

```text
ArithmeticException
```

---

## 例外の継承関係

例外の継承関係は以下のようになっています。
Throwableより下が例外として扱えるクラスです。
これらのクラスにはそれぞれ意味があります。

![picture 12](/images/c86a68901e9b12066119a784f2e39d7540311a1063df9a1f22d7d1346b58954e.png)  

---

### Error

Errorクラスは通常のアプリケーションであれば対処すべきではない重大なエラーのクラスです。
Errorクラスおよびそのサブクラスは、コンパイル時には検出されません。
メモリの枯渇など、プログラマが例外処理を行うべきでないエラーになります。

### Exception

Exceptionクラスはプログラマが対応すべき例外のクラスです。
Exceptionクラスおよび「それ以外のException」クラスは、コンパイル時に検出されます。
Exceptionクラスは「RuntimeException」と「それ以外のException」の親クラスになっています。

### RuntimeException

RuntimeExceptionクラスは潜在的なバグのクラスです。
RuntimeExceptionクラスおよびそのサブクラスは、コンパイル時には検出されません。
先ほど確認したArrayIndexOutOfBoundsExceptionや、ArithmeticExceptionもこのクラスのサブクラスとなります。

ErrorやRuntimeExceptionのように、コンパイル時には検出されない例外を**非チェック例外**といいます。
またExceptionのように、コンパイル時にチェックされる**例外をチェック例外**といいます。

---

## 非チェック例外

コンパイル時にチェックされない例外です。
適切に処理（try ～ catch）されていなくてもコンパイルは通ります。
非チェック例外にはErrorやRuntimeException（とそのサブクラスたち）が該当します。

## チェック例外

コンパイル時にチェックされる例外です。
適切に処理（try ～ catch）されていない場合、コンパイルエラーとなります。
チェック例外にはThrowableやException、それ以外のExceptionが該当します。

---

TryCatchCatchTestクラスを以下のように変更して、実行結果を確認してください。

```java
public class TryCatchCatchTest {
    public static void main(String[] args) {
        int[] array = { 0 };
        try {
            System.out.println(1 / array[0]);
        } catch (ArrayIndexOutOfBoundsException e) {
            System.out.println("ArrayIndexOutOfBoundsException");
        } catch (RuntimeException e) {
            System.out.println("RuntimeException");
        }
    }
}
```

結果

```text
RuntimeException
```

---

このように、多態性を利用することで、ArithmeticExceptionをRuntimeExceptionでcatchすることができます。
また以下のように、RuntimeExceptionとArrayIndexOutOfBoundsExceptionを逆に書くとエラーになります。

```java
public class TryCatchCatchTest {
    public static void main(String[] args) {
        int[] array = { 0 };
        try {
            System.out.println(1 / array[0]);
        } catch (RuntimeException e) {
            System.out.println("RuntimeException");
        } catch (ArrayIndexOutOfBoundsException e) {
            System.out.println("ArrayIndexOutOfBoundsException");
        }
    }
}
```

例外がキャッチできるかどうかのチェックはif-elseと同じように上から順に行われます。
RuntimeExceptionを先に記述するとArrayIndexOutOfBoundsExceptionの例外処理が行われることがなくなるため、コンパイルエラーになります。

---

## 例外を投げる

例外は発生したものを処理するだけでなく、自分から発生させることもできます。（例外を投げるといいます）
以下のプログラムを作成して、実行結果を確認してください。

```java
public class ThrowTest {
    public static void main(String[] args) {
        try {
            throwEx();
        } catch (Exception e) {
            e.printStackTrace();
        }
        System.out.println("終了します");
    }
    public static void throwEx() throws Exception {
        throw new Exception();
    }
}
```

---

結果

```text
java.lang.Exception
    at ThrowTest.throwEx(ThrowTest.java:13)
    at ThrowTest.main(ThrowTest.java:5)
終了します
```

(表示されるメッセージの順番は異なる場合があります)
実行したプログラムの確認をしていきます。

まず大前提として、例外はインスタンスです。
そのため、newで新しく作ることができます。
そして新しく生成した例外インスタンスをthrowで投げています。
このように、例外はthrowというキーワードを使用することで投げる（発生させる）ことができます。

```java
throw new Exception();
```

投げた例外は、呼び出し元のcatchにて処理されています。
Exception」という例外は、「チェック例外」のため、例外処理が行われていないと、コンパイルエラーになります。
throwsはメソッドの呼び出し元に、明示的に「このメソッドではこの例外が発生する」ということを伝えています。
これを書くことで「throwEx」メソッド内での「try ～ catch」は不要になります。
一方で、メソッドの呼び出し元の方で、適切に例外処理を行う必要があります。

---

## finaly

例外が発生した場合、ほとんどの場合は例外処理を行い、「本来の処理」は中断されてしまいます。
このとき、「正常に動作しても、例外が発生しても、必ず行いたい処理」というものがあります。
そのようなときに使えるのがfinallyです。

構文は以下の通りです。
catchを書かずにfinallyだけを書くこともできます。

```java
try {
    処理
} catch (例外の型 変数名) {
    例外発生時の処理
} finally {
    必ず行う処理
}
```

---

以下のプログラムを作成して、実行してください。

```java
public class TryCatchFinallyTest {
    public static void main(String[] args) {
        int[] myarray = new int[3]; // 長さ3の配列

        System.out.println("代入します");
        try {
            myarray[100] = 0; // 100番の箱（用意していない箱）に値を入れる
        } catch (ArrayIndexOutOfBoundsException e) {
            System.out.println("ArrayIndexOutOfBoundsException");
        } finally {
            System.out.println("--例外処理終了--");
        }
        System.out.println("代入しました");
    }
}
```

結果

```text
代入します
ArrayIndexOutOfBoundsException
--例外処理終了--
代入しました
```

---

例外処理(catch内の処理)が発生していますが、finally内の処理は実行されています。
次に以下のように変更して、実行してください。

```java
public class TryCatchFinallyTest {
    public static void main(String[] args) {
        int[] myarray = new int[3]; // 長さ3の配列

        System.out.println("代入します");
        try {
            // myarray[100] = 0; // 100番の箱（用意していない箱）に値を入れる
            myarray[1] = 0; // 1番の箱（用意している箱）に値を入れる
        } catch (ArrayIndexOutOfBoundsException e) {
            System.out.println("ArrayIndexOutOfBoundsException");
        } finally {
            System.out.println("--例外処理終了--");
        }
        System.out.println("代入しました");
    }
}
```

結果

```text
代入します
--例外処理終了--
代入しました
```

---

例外処理(catch内の処理)は発生していませんが、finally内の処理は実行されています。

このように、「finally」を使うことで、「正常に動作しても、例外が発生しても、必ず行いたい処理」を実行させることができます。
例えば、リソースの開放(データベースとの接続を切断する処理やファイルを閉じる処理)などで利用します。

---

## 例外まとめ

Servletに実装していた、doGetメソッドやdoPostメソッドは例外を投げていることが分かります。
ServletExceptionやIOExceptionは例外の名前です。
このメソッドは処理の中で、これらの例外を投げるかもしれない、と宣言しています。

doGetメソッドやdoPostメソッドの呼び出し元(Tomcat)は、自分のところまで飛んできた例外を適切に処理することでプログラムが（この場合は呼び出し元が）止まらないようにしています。
一方で、Webアプリケーションそのものを止めないようにするのは開発者の仕事です。
適切に例外処理をすることで、システム利用者に対して不便をかけないようにする必要があります。

---

## 講義動画

[例外](https://youtu.be/0Xv_81zQvdg)

[警告・エラー](https://youtu.be/CY5tKgw1CC8)
