# 例外

---

## コンパイルエラーと実行時エラー

Javaのエラーには2種類のエラーがあります。
1つはコンパイルエラーで、もう1つは実行時エラーです。

### コンパイルエラー

これはプログラムの文法上のエラーです。
プログラムの書き方がそもそもJavaのルールに従っていない場合に起こるエラーです。
コンパイルエラーがある状態だと、ソースコードをコンパイルするこができないため、当然プログラムの実行もできません。

### 実行時エラー

これは、プログラムの書き方に文法上のミスはないが、実行した時に起こるエラーです。
これを例外（Exception）といいます。

まずは実行時例外が起きるプログラムを見てみましょう。

Main.java

```java
package app;

public class Main {
    public static void main(String[] args) {
        /*
        int型同士の割り算は問題ないため、コンパイルエラーにはならない
        しかし数学的に0による割り算はできないため、エラーになる
        */
        int n = 10 / 0;
        System.out.println(n);
    }
}
```

結果

```text
Exception in thread "main" java.lang.ArithmeticException: / by zero
    at Main.main(Main.java:7)
```

```java
package app;

public class Main {
    public static void main(String[] args) {
        /*
        配列の添え字にint型を使用することは文法上は正しい。
        しかし、この配列の要素数は3なので、使用できる添え字は0～2まで。
        ここでは3を使用しているのでエラーになる。
        */
        int[] nums = {1, 2, 3};
        System.out.println(nums[3]);
    }
}
```

結果

```text
Exception in thread "main" java.lang.ArrayIndexOutOfBoundsException: 3
    at Main.main(Main.java:9)
```

```java
package app;

public class Main {
    public static void main(String[] args) {
        /*
        Stringの変数名.メソッド名()
        によるメソッドの呼び出しは文法上問題ないが
        オブジェクトがnullだった場合はメソッドを呼び出せないため、エラーになる。
        */
        String str = null;
        System.out.println(str.length());
    }
}
```

結果

```text
Exception in thread "main" java.lang.NullPointerException
    at Main.main(Main.java:9)
```

```java
package app;

public class Main {
    public static void main(String[] args) {
        /*
        Integer.parseIntメソッドはString型を引数に取るので、文法としては正しい。
        しかし、"a"は数値に変換できないので、エラーになる。
        */
        String numStr = "a";
        int num = Integer.parseInt(numStr);
        System.out.println(num);
    }
}
```

結果

```java
Exception in thread "main" java.lang.NumberFormatException: For input string: "a"
    at java.lang.NumberFormatException.forInputString(NumberFormatException.java:65)
    at java.lang.Integer.parseInt(Integer.java:580)
    at java.lang.Integer.parseInt(Integer.java:615)
    at Main.main(Main.java:8)
```

```java
package app;

public class Main {
    public static void main(String[] args) {
        /*
        部分文字列を作成しようとしているが、
        文字列の文字数が3文字しかないため、
        10番目の文字列を取得しようとしてもエラーになる。
        */
        String strAbc = "abc";
        String sub = strAbc.substring(10, 15);
        System.out.println(strAbc);
    }
}
```

```text
Exception in thread "main" java.lang.StringIndexOutOfBoundsException: String index out of range: 15
    at java.lang.String.substring(String.java:1963)
    at Main.main(Main.java:9)
```

どのプログラムも正常に結果が出るものはなく、途中でエラーが発生してプログラムが異常終了してしまいます。
ここではエラーの1行目にある
java.lang.XXXXXExceptionE:
という部分に着目してください。
XXXXXの内容がプログラムによって違っているのが分かります。
これは、発生した例外を表すクラスになっています。

例外のクラスは数多くあるため、1つ1つのクラス名を覚える必要はありません。
プログラムをたくさん書いているうちに自然に覚える場合もありますし、クラス名を表す英語の意味が分かればある程度何のエラーかが理解できるようになってきます。
エラーが発生した場合は、慌てずにまずは何のエラーが発生したのかをきちんと見極めるようにしましょう。

## 例外の全体像

Object
|-Trowable
|-Error
|-Exception
    |-RuntimeException
        |-NullPointerExceptionなど
    |-RuntimeException以外（IOExceptionなど）

Javaでは例外は全てクラスになります。
ここでは例外のクラスの全体像を説明します。
まず、Trowableというクラスが例外の最上位のクラスになります。
TrowableのサブクラスとしてErrorとExceptionがあります。

Errorは、例えばJavaのプログラムを実行しようとしたが、メモリの容量が足りずに実行できなかった場合などに発生します。
つまり、プログラムでは対処しようのないものがErrorです。
プログラムの問題ではなく、根本的に別の対処が必要となるものなので、プログラムによる対処は必要ありません。

次にExceptionですが、これが実行時例外になります。
Exceptionは大きく2種類に分けることができます。
1つは、非チェック例外と呼ばれるもので、RuntimeExceptionとそのサブクラスが対象になります。
もう1つはチェック例外と呼ばれるもので、RuntimeException以外とそのサブクラス以外のExceptionです。

## チェック例外と非チェック例外

チェック例外と非チェック例外について詳しく見ていきます。

Main.java

```java
package app;

import java.io.File;

public class Main {
    public static void main(STring[] args) {
        // 非チェック例外
        int n = 10;
        int m = 0;
        System.out.println(n / m);

        // チェック例外
        File file = new File("C:\\\\test\\\\test.java");
        file.createNewFile();
    }
}
```

上の2つの処理は、どちらも例外が発生する可能性のある処理です。
非チェック例外が発生する可能性のある処理は、処理を書いても何の問題もありませんが、チェック例外が発生する可能性のある処理は、そのままではコンパイルエラーになります。
コンパイルエラーを解決するためには、エラーに対する対処をしてあげる必要があります。

### チェック例外と非チェック例外の違い

さて、ではチェック例外と非チェック例外はどういった基準で分かれているのでしょうか。
非チェック例外は基本的にはプログラムのバグです。
例えば先ほどのプログラムでは、0除算のエラーが発生します。
しかし、このプログラム、割る数が0かどうかをif文で判断すればエラーの発生を防ぐことができます。
他にも、配列の要素数を超えたアクセスによるエラーであれば、lengthによってあらかじめ要素数のチェックを行えば防ぐことはできるはずです。
このように、if文などを使用して、プログラムをきちんと書けば例外の発生を防げるものが非チェック例外です。
プログラムを直せば発生しなくなるものなので、例外の対処をする必要はありません。
このような例外はコンパイラによってチェックをしない、というわけです。

一方でチェック例外は、処理が正常に行われるか失敗するかが環境や状況によって左右されます。

```java
File file = new File("C:\\\\test\\\\test.java");
file.createNewFile();
```

先の例で書いたプログラムは、C:\testのフォルダにtest.javaというファイルを作成するプログラムです。
実行したPCのCドライブ直下に「test」というフォルダが存在すれば処理は成功して例外は発生しません。
一方、「test」というフォルダが存在しなかった場合は、例外が発生します。
つまり、同じプログラムであっても、実行する環境やタイミングによって成功したり失敗したりする可能性がある。
そのときに発生する例外がチェック例外です。

ファイル操作以外でも、例えばデータベースに対する処理の場合、
ソースコードでエラーにならないように細かくチェックしていても、接続先のデータベースに異常があれば失敗する可能性があります。
ネットワーク経由でデータを取得するようなプログラムの場合、そもそもネットワークがつながっていなければ実行しようがありません。
このように、プログラムが正しくても環境や状況によって失敗の可能性がある処理はあらかじめ例外の発生に備えて対処をしておく必要がある、ということです。

## try~catch

先の例で見たチェック例外が発生するプログラムの場合、例外の対処をしてあげる必要があります。
例外の対処方法は2つあります。
そのうちの1つ目の対処方法がtry~catchです。
例外が発生する可能性のある処理を、try句の中に書きます。
例外が発生した場合の処理をcatch句の中に書きます。
これにより、例外が発生した場合でも、プログラムが異常終了することなく、引き続き処理が実行されます。

構文

```java
try {
    例外が発生する可能性のある処理
} catch (発生するExceptionの型 変数名) {
    例外が発生した場合の処理
}
```

Main.java

```java
package app;

import java.io.File;
import java.io.IOException;

public class Main {
    public static void main(String[] args) {

        File file = new File("C:\\\\test\\\\test.java");
        try {
            file.createNewFile();
            System.out.println("ファイル作成完了");
        } catch (IOException e) {
            System.out.println("エラー発生！");
            e.printStackTrace(); // コンソールにエラー情報を出力する処理
        }
    }
}
```

結果
※環境によって結果が変わります。
C:\testフォルダがあればエラーは発生しません。

```text
エラー発生！
java.io.IOException: 指定されたパスが見つかりません。
    at java.io.WinNTFileSystem.createFileExclusively(Native Method)
    at java.io.File.createNewFile(File.java:1012)
    at Main.main(Main.java:9)
```

エラーが発生したらcatch句の中の処理が実行されます。
eには発生したExceptionクラスのインスタンスが入っています。
ExceptionクラスのprintStackTraceメソッドはコンソールにエラー情報が出力されます。

次の例を見てみましょう。
catch句は複数書くことができます。
※この例は非チェック例外なので例外対処は必要ありませんが、try~catchの中で学習のために使用しています。

Main.java

```java
package app;

public class Main {
    public static void main(String[] args) {
        // catch句は複数書くことができます。
        try {
            String str = null;
            String sub;
            sub = str.substring(10);
            System.out.println(sub);
        } catch (NullPointerException e) {
            System.out.println("NullPointer");
        } catch (IndexOutOfBoundsException e) {
            System.out.println("IndexOutOfBounds");
        }
    }
}
```

結果

```text
NullPointer
```

複数のExceptionをcatchする場合、|で区切って複数書くことができます。

Main.java

```java
package app;

public class Main {
    public static void main(String[] args) {
        // 一つのキャッチ句にまとめて書くことも可能
        try {
            String str = null;
            String sub = str.substring(10);
            System.out.println(sub);
        } catch (NullPointerException | IndexOutOfBoundsException e) {
            e.printStackTrace();
        }
    }
}
```

結果

```text
java.lang.NullPointerException
    at Main.main(Main.java:6)
```

catch句にはポリモーフィズムが適用されます。

Main.java

```java
package app;

public class Main {
    public static void main(String[] args) {
        // 例外のcatchにもポリモーフィズムが働く
        // スーパークラスのExceptionでcatchすることもできる
        // 非チェック例外はRuntimeExceptionのサブクラスなので、
        // 非チェック例外ならRuntimeExceptionで対処できる
        try {
            System.out.println(10 / 0);
        } catch (RuntimeException e) {
            System.out.println("RuntimeException");
        }
    }
}
```

結果

```text
RuntimeException
```

```java
public class Main {
    public static void main(String[] args) {
        // こちらはコンパイルエラー
        // 継承関係で親に値するクラスが先に書かれている場合、
        // サブクラスのcatchは通らくなるため、コンパイルエラー
        try {
            System.out.println(10 / 0);
        } catch (Exception e) {
            System.out.println("Exception");
        } catch (RuntimeException e) {
            System.out.println("RuntimeException");
        }
    }
}
```

例外が発生した場合でも、発生しなかった場合でも、どちらの場合でも確実に実行したい処理もあります。
そのような場合はfinaly句を使用します。

```java
package app;

public class Main {
    public static void main(String[] args) {
        // finally句
        // 処理が正常の終了しようが、例外が発生しようが、どちらにせよ必ず実行したい処理がある場合もある
        // その場合、catch句の後にfinally句を使用することで実現可能
        // DB操作やファイル操作、ネットワーク関連の処理などでは、リソースを使用した後に開放する処理が必要で
        // そのような場合にfinallyが使用される
        try {
            int n = 10 / 0;
            System.out.println(n);
        } catch (Exception e) {
            System.out.println("例外発生");
        } finally {
            System.out.println("絶対に通る");
        }

    }
}
```

結果

```text
例外発生
絶対に通る
```

## throws宣言

try~catchを使用しない例外の対処方法があります。
それがthrows宣言です。
try~catchは、例外が発生する可能性のある処理に対して、自分自身で対応する方法でした。
一方でthrowsは、自分で例外の処理を行わず、呼び出し元に任せてしまう方法です。
メソッド宣言でメソッド名の後に、「throws 発生するException名」で定義します。

メソッドの宣言部に「throws 発生する可能性のあるException」
を付けることで、try~catchによる例外対処が不要になります。
その場合、メソッドの呼び出し元に例外対処を任せることになります。
呼び出し元のメソッドでtry~catchにより対処するか、
呼び出し元のメソッドでもthrows宣言をして、更に呼び出し元に任せて例外を対処します。

Main.java

```java
import java.io.File;
import java.io.IOException;

public class Main {

    // throws宣言のあるメソッドを呼び出す場合は、例外の対処が必要
    // そのメソッドをtry~catchで囲って対処。またはthrows宣言をしてさらに呼び出し元に任せる
    // mainメソッドでthrows宣言をした場合、JVMが処理することになり、例外発生時点でプログラムは終了する
    public static void main(String[] args) {
        try {
            createJavaFile()
        } catch (IOException e) {
            e.printStackTrace();
        }
    }

    // 呼び出し元に例外処理を任せる
    // throws宣言を書くことで、try~catchが不要になる
    public static void createJavaFile() throws IOException {
        File file = new File("C:\\\\test\\\\test.java");
        file.createNewFile();
    }
}
```

結果

```text
java.io.IOException: 指定されたパスが見つかりません。
    at java.io.WinNTFileSystem.createFileExclusively(Native Method)
    at java.io.File.createNewFile(File.java:1012)
    at Main.createJavaFile(Main.java:21)
    at Main.main(Main.java:11)
```

非チェック例外の場合は、例外の対処がいらないため、
throws宣言されていても対処の必要ありません。
この例では例外は対処されずプログラムが強制終了します。

Main.java

```java
package app;

public class Main {

    public static void main(String[] args) {
        int n = calc();
        System.out.println(n);
    }

    public static int calc() throws RuntimeException {
        return 10 / 0;
    }
}
```

## 例外を作成・発生させる

Javaでは例外はクラスのため、自分で作成することもできます。
チェック例外を作成したい場合は、Exceptionクラスを継承して例外を作成します。
非チェック例外を作成したい場合は、RuntimeExceptionクラスを継承して例外を作成します。

また作成した例外は自分で発生させることもできます。
例外を発生させる場合はthrowを使用します。

SampleException.java

```java
package app;

// チェック例外
public class SampleException extends Exception {

}
```

SampleRuntimeException.java

```java
package app;

// 非チェック例外
public class SampleRuntimeException extends RuntimeException {

}
```

Main.java

```java
package app;

// 動作検証
public class Main {
    public static void main(String[] args) {

        try {
            // 例外の対処が必要
            sampleExceptionTest();
        } catch (SampleException e) {
            e.printStackTrace();
        }

        // 例外対処不要
        sampleRuntimeExceptionTest();

    }

    public static void sampleExceptionTest() throws SampleException {
        throw new SampleException();
    }

    public static void sampleRuntimeExceptionTest() {
        throw new SampleRuntimeException();
    }
}
```

## 例外とオーバーライド

例外、その中でもthrowsについては、オーバーライドとも深い関わりがあります。
まずは以下のサンプルを確認してください。

Super.java

```java
package app;

import java.io.File;
import java.io.IOException;

public class Super {

    // 例外は発生する可能性のあるメソッド
    public void method() throws IOException {
        final File file = new File("C:\\\\test\\\\Main.java");
        file.createNewFile();
    }

}
```

Sub.java

```java
package app;

import java.io.IOException;

// Superを継承
public class Sub extends Super {

    @Override
    public void method() throws IOException {
       super.method();
    }

}
```

```java
package app;

import java.io.IOException;

// 動作確認
public class Main {
    public static void main(String[] args) {
        Super s = new Sub();
        try {
            s.method();
        } catch (IOException e) {
            e.printStackTrace();
        }
    }
}
```

この例では例外が発生する可能性のあるメソッドをもつSuperクラスをSubクラスが継承しています。
Mainクラスではポリモーフィズムを利用し、Subのインスタンスでメソッドを呼び出します。
メソッドは例外が発生する可能性があるため、try~catchで囲っています。
この時、Subクラスのmethodのthrows宣言で、発生する可能性のある例外をExceptionに変更してみます。

```java
@Override
// throws宣言をExceptionに変更する
public void method() throws Exception {
   super.method();
}
```

そうすると、Subクラスでコンパイルエラーが発生します。
これはthrows宣言での例外のクラスを、継承元のメソッドでの例外よりも上位の例外に変更できないことを示しています。
オーバーライドする際になぜ発生する例外のクラスを上位のクラスにできないかというと、呼び出し元に影響が出てしまうからです。
この例で仮にオーバーライドしたメソッドのthrows宣言でExceptionを指定することができたとすると、それを使用するMainクラスのtry~catchの内容を変更する必要が出てきます。
これは、呼び出しの処理を変更せずに処理の中身を変更することができるというポリモーフィズムのメリットが失われてしまう事を示しています。
ポリモーフィズムの機能がうまく動作するように、オーバーライドしたメソッドで発生する例外のクラスを広げることはできない仕組みになっています。

## 例外対処の必要性

これまで、どんな場合に例外が発生するのか、
また、どうやって例外の対処をするかを学習しました。
しかし、そもそもなぜ例外の対処をする必要があるのでしょうか。

もし例外の対処をしないでそのままにしていると、
プログラムの途中で例外が発生した場合、その時点でプログラムが異常終了してしまいます。
Webサービスなど、不特定多数の人が利用するプログラムの場合、
例外が発生してサービスが利用できなくなってしまっては困ります。

プログラムで想定外の事態が発生しても、
利用者がサービスの利用を続けることができるように、例外の対処をする必要があります。

### 例外のまとめ

- エラーにはコンパイルエラーと実行時エラーの2種類がある
- 実行時エラーのことを例外（Exception）と呼ぶ
- 例外にはチェック例外と非チェック例外がある
- 基本的には非チェック例外はプログラムのバグで、例外対処は必要ない
- チェック例外は環境に依存するエラーで必ず対処が必要
- 例外の対処の方法はtry~catchとthrowsの2種類がある
- try~catchは自分で例外を処理し、throwsはメソッドの呼び出し元に任せる

## 講義動画

[例外](https://youtu.be/0Xv_81zQvdg)

[警告・エラー](https://youtu.be/CY5tKgw1CC8)
